Workbook

Sheet Dashboard
A1: SHARJAH CHARITY INTERNATIONAL - QA BUG TRACKER DASHBOARD
A2: Money Box Module – New Design | Testing Period: 06 June 2026 | Source: Uploaded QA Testing Report
A4: Total Bugs | B4: Total Bugs | C4: Open | D4: Open | E4: High Severity | F4: High Severity | G4: High Priority | H4: High Priority | I4: Report/PDF Issues | J4: Report/PDF Issues | K4: Missing Field/Column | L4: Missing Field/Column
A5: =COUNTA('Bug Tracker'!$A$2:$A$100) -> 22 | C5: =COUNTIF('Bug Tracker'!$K$2:$K$100,"Open") -> 22 | E5: =COUNTIF('Bug Tracker'!$I$2:$I$100,"High") -> 14 | G5: =COUNTIF('Bug Tracker'!$J$2:$J$100,"High") -> 18 | I5: =COUNTIF('Bug Tracker'!$H$2:$H$100,"Report/PDF") -> 5 | K5: =COUNTIF('Bug Tracker'!$H$2:$H$100,"Missing Field/Column") -> 4
A7: Severity Mix | D7: Priority Mix | G7: Status Mix
A8: Severity | B8: Count | D8: Priority | E8: Count | G8: Status | H8: Count
A9: High | B9: =Summary!B4 -> 14 | D9: High | E9: =Summary!E4 -> 18 | G9: Open | H9: =Summary!H4 -> 22
A10: Medium / High | B10: =Summary!B5 -> 3 | D10: Medium | E10: =Summary!E5 -> 4 | G10: In Progress | H10: =Summary!H5 -> 0
A11: Medium | B11: =Summary!B6 -> 4 | D11: Low | E11: =Summary!E6 -> 0 | G11: Blocked | H11: =Summary!H6 -> 0
A12: Low / Medium | B12: =Summary!B7 -> 1 | D12: Critical | E12: =Summary!E7 -> 0 | G12: Ready for Retest | H12: =Summary!H7 -> 0
A13: Low | B13: =Summary!B8 -> 0 | G13: Closed | H13: =Summary!H8 -> 0
A16: Executive QA Notes
A17: 1 | B17: Most issues are open and require development analysis/retest.
A18: 2 | B18: Critical focus areas: save/add failures, missing columns/fields, report PDF processing errors, and old-vs-new design data mismatch.
A19: 3 | B19: Recommended QA action: fix High priority bugs first, retest affected screens, then complete regression on Money Box workflows.

Sheet Bug Tracker
A1: Bug ID | B1: Bug Title | C1: Module | D1: Sub Module | E1: Screen/Page | F1: URL | G1: Defect Type | H1: Category | I1: Severity | J1: Priority | K1: Status | L1: Assigned To | M1: Reported By | N1: Reported Date | O1: Target Fix Date | P1: Environment | Q1: Actual Result | R1: Expected Result | S1: Steps to Reproduce | T1: Description | U1: Evidence/Page Ref | V1: Remarks
A2: MB-ND-001 | B2: Old request/record becomes hidden after editing and saving in Money Boxes screen | C2: Money Box / الحصالات | E2: Money Boxes / الحصالات | F2: https://10.10.10.154:200/moneybox/moneyBoxes | G2: Functional | H2: Data Display/Refresh | I2: High | J2: High | K2: Open | L2: Development Team | M2: Abida Gul | N2: 46179 | O2: 46182 | P2: ERP Application - New Design | Q2: After editing and saving the old request, the record becomes hidden or does not appear properly in the table. | User cannot clearly confirm whether the update was saved successfully. | Table/list view does not refresh or display the updated record correctly. | R2: After editing and saving, the updated record should remain visible in the table. | The table should refresh properly and show the latest updated data. | User should receive a success message after saving. | No record should disappear or become hidden after update. | S2: Open the Money Boxes screen using this URL: | https://10.10.10.154:200/moneybox/moneyBoxes | Search or select an existing/old request from the table. | Click on the تعديل button for any existing record. | Update any required field. | Click the save/update button. | Return to the table/list view. | Observe that the edited record is hidden or not displayed correctly in the table. | T2: When the user edits an existing/old request from the table and then clicks save, the updated request/record becomes hidden or does not display properly in the table. The record should remain visible after saving, but instead it appears to disappear or hide from the list. | U2: Document bug #1 | V2: Pending developer analysis
A3: MB-ND-002 | B3: Error occurs when adding new Money Box and clicking Save | C3: Money Box / الحصالات | E3: Money Boxes / الحصالات | F3: https://10.10.10.154:200/moneybox/moneyBoxes | G3: Functional | H3: Add/Save Error | I3: High | J3: High | K3: Open | L3: Development Team | M3: Abida Gul | N3: 46179 | O3: 46182 | P3: ERP Application - New Design | Q3: The system displays an error message after clicking حفظ. | New Money Box is not saved. | User cannot complete the add process successfully. | Error message appears | "حدث خطأ. يرجى التواصل مع الدعم الفني إذا استمر هذا الخطأ" | R3: New Money Box should be saved successfully. | System should show a success message after saving. | The newly added Money Box should appear in the Money Boxes table/list. | No error message should appear. | S3: Open the Money Boxes screen using the URL: | https://10.10.10.154:200/moneybox/moneyBoxes | Click on the إضافة / Add button. | The إضافة حصالة جديدة form will open. | Fill in the required fields, such as: | نوع / Type | كود رئيسي / Main Code | كود / Code | الرقم / Number | تصنيف الحصالة / Money Box Classification | Click on the حفظ button. | Observe the error message displayed on the screen. | T3: When the user tries to add a new Money Box from the Money Boxes / الحصالات screen and clicks the حفظ button, the system shows an error message and the new Money Box is not saved. | The error message displayed is: | "حدث خطأ. يرجى التواصل مع الدعم الفني إذا استمر هذا الخطأ" | Translation: "An error occurred. Please contact technical support if this error continues." | U3: Document bug #2 | V3: Pending developer analysis
A4: MB-ND-003 | B4: Error occurs when adding new Section Grouping and clicking Save | C4: Money Box / الحصالات | D4: Section Grouping / مجموعة الحصالات | E4: Money Boxes → Sections Grouping / مجموعة الحصالات | F4: https://10.10.10.154:200/moneybox/sections/sectionsGrouping/a64e09d7-5f17-eb11-81d7-000c29d5b0c7 | G4: Functional | H4: Add/Save Error | I4: High | J4: High | K4: Open | L4: Development Team | M4: Abida Gul | N4: 46179 | O4: 46182 | P4: ERP Application - New Design | Q4: The system displays an error message after clicking حفظ. | New Section Grouping is not saved. | User cannot complete the add process successfully. | Error message appears: | "حدث خطأ. يرجى التواصل مع الدعم الفني إذا استمر هذا الخطأ" | R4: New Section Grouping should be saved successfully. | System should show a success message after saving. | The newly added Section Grouping should appear in the list/table. | No error message should appear. | S4: Open the Section Grouping screen using the URL: | https://10.10.10.154:200/moneybox/sections/sectionsGrouping/a64e09d7-5f17-eb11-81d7-000c29d5b0c7 | Click on the إضافة / Add button. | The إضافة مجموعة form will open. | Fill in the required fields, such as: | التصنيف / Classification | رقم المجموعة / Group Number | Click on the حفظ button. | Observe the error message displayed on the screen. | T4: When the user tries to add a new Section Grouping from the Money Boxes section and clicks the حفظ button, the system shows an error message and the new section grouping is not saved. | The error message displayed is: | "حدث خطأ. يرجى التواصل مع الدعم الفني إذا استمر هذا الخطأ" | Translation: "An error occurred. Please contact technical support if this error continues." | U4: Document bug #3 | V4: Pending developer analysis
A5: MB-ND-004 | B5: Add button is missing in Assign Money Box subsection screen | C5: Money Box / الحصالات | D5: Assign Money Box / تعيين حصالة | E5: Money Boxes → Sections → Assign Money Box / تعيين حصالة | F5: https://10.10.10.154:200/moneybox/sections/assignMoneybox/3ff57db3-3d62-f111-8272-000c29b5ee4d | G5: Functional | H5: Missing Field/Column | I5: Medium / High | J5: High | K5: Open | L5: Development Team | M5: Abida Gul | N5: 46179 | O5: 46182 | P5: ERP Application - New Design | Q5: Add / إضافة button is missing from the subsection screen. | User cannot add or assign a new Money Box. | User is unable to perform the required assignment action from this page. | R5: Add / إضافة button should be available on the Assign Money Box subsection screen. | User should be able to click the Add button and assign a new Money Box. | The newly assigned Money Box should appear in the table/list after saving. | S5: Open the Assign Money Box screen using the URL: | https://10.10.10.154:200/moneybox/sections/assignMoneybox/3ff57db3-3d62-f111-8272-000c29b5ee4d | Check the top section of the page. | Check the Money Boxes table/list area. | Check the Assign Money Box section. | Observe that there is no Add / إضافة button available. | T5: On the Assign Money Box subsection screen, the Add / إضافة button is missing. Because of this, the user cannot add or assign a new Money Box from this screen. | The screen shows the Money Box list and Assign Money Box section, but there is no button available to add a new record. | U5: Document bug #4 | V5: Pending developer analysis
A6: MB-ND-005 | B6: Group title/alignment is not displayed properly on Assign Money Box screen | C6: Money Box / الحصالات | D6: Assign Money Box / تعيين حصالة | E6: Money Boxes → Sections → Assign Money Box / تعيين حصالة | F6: https://10.10.10.154:200/moneybox/sections/assignMoneybox/3ff57db3-3d62-f111-8272-000c29b5ee4d | G6: UI/UX | H6: UI/UX | I6: Low / Medium | J6: Medium | K6: Open | L6: Development Team | M6: Abida Gul | N6: 46179 | O6: 46186 | P6: ERP Application - New Design | Q6: Group title is not aligned properly. | Arabic and English text appear mixed incorrectly. | The displayed title looks like: | رقم المجموعة : 3510 ----------- Test project | Text direction/spacing is not properly handled. | R6: Group title should be displayed clearly and properly aligned. | Arabic and English text should follow correct RTL/LTR formatting. | The title should appear in a clean and readable format, for example: | رقم المجموعة: 3510 - Test project | No broken spacing or unnecessary dashes should appear. | S6: Open the Assign Money Box screen using this URL: | https://10.10.10.154:200/moneybox/sections/assignMoneybox/3ff57db3-3d62-f111-8272-000c29b5ee4d | Check the group title displayed at the top-right side of the page. | Observe the text formatting and alignment. | T6: On the Assign Money Box / تعيين حصالة screen, the group title is not displayed properly. The text: | رقم المجموعة : 3510 ----------- Test project | appears with incorrect alignment/formatting. The Arabic and English text are mixed in the same line and the direction/alignment looks broken. This affects readability and makes the page look inconsistent. | U6: Document bug #5 | V6: Pending developer analysis
A7: MB-ND-006 | B7: Deleted record shows success message but data is not removed from Sub Money Box Type list | C7: Money Box / الحصالات | D7: Sub Money Box Type / نوع الحصالات الفرعي | E7: Money Boxes → Sub Money Box Type / نوع الحصالات الفرعي | F7: https://10.10.10.154:200/moneybox/moneyboxSubTypes | G7: Functional | H7: Delete | I7: Medium / High | J7: High | K7: Open | L7: Development Team | M7: Abida Gul | N7: 46179 | O7: 46182 | P7: ERP Application - New Design | Q7: System shows success message: | "تم الحذف بنجاح" | The selected record is still visible in the list. | Data is not removed from the table after delete. | User cannot confirm whether the record was actually deleted from the database or only the UI failed to refresh. | R7: After clicking Delete, the selected record should be removed successfully. | The deleted record should disappear from the table/list. | Table should refresh automatically after successful deletion. | Success message should appear only when the record is actually deleted. | S7: Open the Sub Money Box Type screen using the URL: | https://10.10.10.154:200/moneybox/moneyboxSubTypes | Select any existing record from the list. | Click on the حذف / Delete button. | Confirm the delete action, if confirmation popup appears. | Observe the success message. | Check the table/list after deletion. | T7: When the user deletes a record from the Sub Money Box Type / نوع الحصالات الفرعي screen, the system displays a success message saying that the record has been deleted successfully. However, the deleted record still remains visible in the table/list and is not removed from the screen. | The success message displayed is: | "تم الحذف بنجاح" | Translation: "Deleted successfully" | U7: Document bug #6 | V7: Pending developer analysis
A8: MB-ND-007 | B8: New Sub Money Box Type shows success message but data is not added in the list | C8: Money Box / الحصالات | D8: Sub Money Box Type / نوع الحصالات الفرعي | E8: Money Boxes → Sub Money Box Type / نوع الحصالات الفرعي | F8: https://10.10.10.154:200/moneybox/moneyboxSubTypes | G8: Functional | H8: Data Display/Refresh | I8: High | J8: High | K8: Open | L8: Development Team | M8: Abida Gul | N8: 46179 | O8: 46182 | P8: ERP Application - New Design | Q8: System shows a success message after saving. | Newly added data does not appear in the list/table. | User cannot confirm whether the data was saved successfully. | The table does not refresh or display the newly added record. | R8: After clicking Save, the new record should be saved successfully. | The newly added Sub Money Box Type should appear in the list/table immediately. | Table should refresh automatically after saving. | Success message should appear only when the record is actually saved and visible in the list. | S8: Open the Sub Money Box Type screen using the URL: | https://10.10.10.154:200/moneybox/moneyboxSubTypes | Click on the إضافة / Add button. | Enter the required details for the new Sub Money Box Type. | Click on the حفظ / Save button. | Observe the success message. | Check the list/table after saving. | T8: When the user adds a new record in the Sub Money Box Type / نوع الحصالات الفرعي screen and clicks Save, the system displays a success message. However, the newly added data does not appear in the list/table after saving. | The success message appears, but the record is not visible, so the user cannot confirm whether the data was actually saved in the database or if the table failed to refresh. | U8: Document bug #7 | V8: Pending developer analysis
A9: MB-ND-008 | B9: Error occurs when changing Active/Inactive status in Field Committee List screen | C9: Money Box / الحصالات | D9: Field Committee List / قائمة اللجنة الميدانية | E9: Money Boxes → Field Committee List / قائمة اللجنة الميدانية | F9: https://10.10.10.154:200/moneybox/outFieldCommitteeList | G9: Functional | H9: Status/Toggle | I9: High | J9: High | K9: Open | L9: Development Team | M9: Abida Gul | N9: 46179 | O9: 46182 | P9: ERP Application - New Design | Q9: System displays an error message after clicking the status toggle. | Active/Inactive status is not updated. | User cannot enable or disable the selected record. | Error message appears: | "حدث خطأ. يرجى التواصل مع الدعم الفني إذا استمر هذا الخطأ" | R9: User should be able to change the status successfully. | Toggle should update from Active to Inactive or Inactive to Active without error. | System should show a success message after status update. | Updated status should remain saved after refreshing the page. | S9: Open the Field Committee List screen using the URL: | https://10.10.10.154:200/moneybox/outFieldCommitteeList | Go to the records list/table. | Select any record. | Click on the Active/Inactive toggle under the فعال / Active column. | Observe the error message displayed on the screen. | T9: When the user tries to change the status using the Active/Inactive toggle in the Field Committee List / قائمة اللجنة الميدانية screen, the system displays an error message and the status is not updated successfully. | The error message displayed is: | "حدث خطأ. يرجى التواصل مع الدعم الفني إذا استمر هذا الخطأ" | Translation: "An error occurred. Please contact technical support if this error continues." | U9: Document bug #8 | V9: Pending developer analysis
A10: MB-ND-009 | B10: New Field Committee record shows success message but data is not displayed in the table | C10: Money Box / الحصالات | D10: Field Committee List / قائمة اللجنة الميدانية | E10: Money Boxes → Field Committee List / قائمة اللجنة الميدانية | F10: https://10.10.10.154:200/moneybox/outFieldCommitteeList | G10: Functional | H10: Data Display/Refresh | I10: High | J10: High | K10: Open | L10: Development Team | M10: Abida Gul | N10: 46179 | O10: 46182 | P10: ERP Application - New Design | Q10: System shows success message: | "نجاح - تم الحفظ بنجاح" | Newly added record does not appear in the table/list. | User cannot confirm whether the data was saved successfully. | Table does not refresh or display the newly added data. | R10: After clicking Save, the new Field Committee record should be saved successfully. | The newly added record should appear in the table/list immediately. | Table should refresh automatically after saving. | Success message should appear only when the saved data is visible or correctly added. | S10: Open the Field Committee List screen using the URL: | https://10.10.10.154:200/moneybox/outFieldCommitteeList | Click on the إضافة / Add button. | Enter the required details for the new Field Committee record. | Click on the حفظ / Save button. | Observe the success message displayed on the screen. | Check the table/list after saving. | T10: When the user adds a new record in the Field Committee List / قائمة اللجنة الميدانية screen and clicks Save, the system displays a success message. However, the newly added data does not appear in the table/list after saving. | The success message appears, but the record is not visible in the list, so the user cannot confirm whether the data was actually saved in the database or if the table failed to refresh. | Success message displayed: | "نجاح - تم الحفظ بنجاح" | Translation: "Success - Saved successfully" | U10: Document bug #9 | V10: Pending developer analysis
A11: MB-ND-010 | B11: Employee Name and Committee Name fields are missing in new Committee Members screen | C11: Money Box / الحصالات | D11: Field Committee Members / أعضاء لجنة الحصالات | E11: Money Boxes → Field Committee Members / أعضاء لجنة الحصالات | F11: https://10.10.10.154:200/moneybox/outFieldCommitteeMembers | G11: Functional | H11: Missing Field/Column | I11: High | J11: High | K11: Open | L11: Development Team | M11: Abida Gul | N11: 46179 | O11: 46182 | P11: ERP Application - New Design | Q11: Employee Name field is not available in the new screen. | Committee Name field is not available in the new screen. | User cannot select/search employee name properly. | User cannot select/search committee name properly. | New screen does not match the old screen functionality. | R11: New screen should include the same required fields as the old screen. | Employee Name / اسم الموظف field should be available. | Committee Name / اللجنة المؤقتة field should be available. | User should be able to search/filter or add committee members using these fields. | Functionality should remain the same as the old screen. | S11: Open the Field Committee Members screen using the URL: | https://10.10.10.154:200/moneybox/outFieldCommitteeMembers | Check the search/add section at the top of the page. | Compare it with the old screen/design. | Observe that the following fields are missing in the new screen: | Employee Name / اسم الموظف | Committee Name / اللجنة المؤقتة | T11: In the old screen/design, the user had fields for selecting or entering: | اسم الموظف / Employee Name | اللجنة المؤقتة / Committee Name | But in the new screen, these fields are not available. Because of this, the user cannot search, filter, or add committee members properly using employee name and committee name. | The required fields are missing from the new UI compared to the old screen. | U11: Document bug #10 | V11: Pending developer analysis
A12: MB-ND-011 | B12: PDF report shows processing error when opening Money Box Key Report receipt | C12: Money Box / الحصالات | D12: Field Committee / Add Committee / Receipt Report | E12: Money Boxes → Field Committee / Add Committee → Receipt / الإيصال | F12: https://10.10.10.154:200/moneybox/fieldCommittee/addCommittee/86fc4df7-9249-eb11-8336-00056d818d71 | G12: Report | H12: Report/PDF | I12: High | J12: High | K12: Open | L12: Development Team | M12: Abida Gul | N12: 46179 | O12: 46182 | P12: ERP Application - New Design | Q12: PDF viewer opens successfully. | Report content is not generated correctly. | PDF shows a report processing error instead of receipt/report details. | User cannot print or verify the Money Box Key Report. | Error visible in the PDF: | “An error has occurred while processing Table ‘table1’.” | R12: MoneyBoxKeyReport should generate successfully. | PDF should display the correct receipt/report details. | User should be able to view, download, and print the report without any error. | No report processing or dataset error should appear. | S12: Open the Field Committee/Add Committee screen using the URL: | https://10.10.10.154:200/moneybox/fieldCommittee/addCommittee/86fc4df7-9249-eb11-8336-00056d818d71 | Click on the report/receipt option. | PDF viewer opens with report name: | MoneyBoxKeyReport | Observe the generated PDF content. | T12: When the user opens or generates the MoneyBoxKeyReport PDF report from the Field Committee/Add Committee screen, the PDF viewer opens but the report is not generated correctly. Instead of showing the proper receipt/report data, the PDF displays a report processing error. | The error shown inside the PDF is related to processing the report table and dataset execution. | U12: Document bug #11 | V12: Pending developer analysis
A13: MB-ND-012 | B13: Committee Report PDF displays processing error instead of complete report data | C13: Money Box / الحصالات | D13: Field Committee Report / لجنة تحصيل رسوم فتح الحصالات | E13: Money Boxes → Field Committee Report / لجنة تحصيل رسوم فتح الحصالات | F13: https://10.10.10.154:200/91b1957d-b0b2-49a6-a356-6192984f4bed | G13: Report | H13: Report/PDF | I13: High | J13: High | K13: Open | L13: Development Team | M13: Abida Gul | N13: 46179 | O13: 46182 | P13: ERP Application - New Design | Q13: PDF viewer opens successfully. | Report layout appears partially. | A red error message appears inside the PDF. | Report data is not loaded completely. | User cannot use the report for printing or official processing. | Error shown: | “An error has occurred while processing Table ‘table1’.” | R13: Committee report PDF should generate successfully. | All report data should display correctly. | No processing/table error should appear inside the PDF. | User should be able to view, download, and print the report properly. | S13: Open the Money Box module. | Navigate to the Field Committee / Committee Report section. | Generate or open the committee report PDF. | PDF viewer opens in the browser. | Observe the report content on page 1. | T13: When the user opens/generates the committee PDF report, the PDF viewer opens and the report layout is partially displayed. However, the report shows a processing error inside the PDF content instead of generating the complete report data. | The report displays the Sharjah Charity International logo and some form fields, but the main report data is not generated correctly due to a report processing/table error. | The error visible in the PDF is: | “An error has occurred while processing Table ‘table1’.” | U13: Document bug #12 | V13: Pending developer analysis
A14: MB-ND-013 | B14: Service Name dropdown shows empty list in External Collections screen | C14: Money Box / الحصالات | D14: External Collections / التحصيلات الخارجية | E14: Money Boxes → External Collections / التحصيلات الخارجية | F14: https://10.10.10.154:200/moneybox/outSideCollections/outSideCollection/b1533dec-5a62-f111-8272-000c29b5ee4d | G14: Localization | H14: Dropdown/Localization | I14: Medium / High | J14: High | K14: Open | L14: Development Team | M14: Abida Gul | N14: 46179 | O14: 46182 | P14: ERP Application - New Design | Q14: Service Name dropdown opens. | Dropdown list is empty. | No service names are displayed for selection. | User cannot select the required service. | R14: Service Name dropdown should display the available service names. | User should be able to select a service from the list. | Dropdown data should load properly without empty records. | Search/filter should work according to the selected service. | S14: Open the External Collections screen using the URL: | https://10.10.10.154:200/moneybox/outSideCollections/outSideCollection/b1533dec-5a62-f111-8272-000c29b5ee4d | Go to the top-right section of the page. | Click on the اسم الخدمة / Service Name dropdown. | Observe the dropdown list. | T14: When the user opens the External Collections / التحصيلات الخارجية screen and clicks on the اسم الخدمة / Service Name dropdown, the dropdown list opens but no service records are displayed. The list appears empty, so the user cannot select any service name. | Because of this issue, the user may not be able to filter/search the external collection records properly or complete the required process where service selection is needed. | U14: Document bug #13 | V14: Pending developer analysis
A15: MB-ND-014 | B15: List/Data Not Displayed in New Design While Same Data Appears Correctly in Old Design – Money Boxes Screen (Money box Test 1011) | C15: Money Box / الحصالات | E15: Money Boxes / الحصالات | F15: https://10.10.10.154:200/moneybox/moneyBoxes | G15: Functional | H15: Data Display/Refresh | I15: High | J15: High | K15: Open | L15: Development Team | M15: Abida Gul | N15: 46179 | O15: 46182 | P15: ERP Application - New Design | Q15: Records are displayed correctly in the old design. | The same records are missing or not visible in the new design. | Users cannot access or view the expected data from the new screen. | Data consistency between old and new designs is not maintained. | R15: The new design should display the same records as the old design. | Data count and list results should be consistent across both versions. | Users should be able to view all available records without any missing data. | Search and filtering functionality should return identical results in both designs. | S15: Open the Money Boxes screen in the Old Design. | Verify that records/data are displayed correctly in the list. | Open the same screen in the New Design. | Use the same search criteria or default view. | Compare the results between both screens. | Observe that records visible in the old design are not displayed in the new design. | T15: In the Money Boxes screen, the records/list are displayed correctly in the old design, but the same records are not displayed in the new design. Although data exists in the system and is visible in the old screen, the new screen fails to load or show the list properly. This creates inconsistency between the old and new versions and prevents users from viewing available records. | U15: Document bug #14 | V15: Pending developer analysis
A16: MB-ND-015 | B16: Missing Columns in New Design Compared to Old Design – Money Boxes List Screen | C16: Money Box / الحصالات | E16: Money Boxes / الحصالات | F16: https://10.10.10.154:200/moneybox/moneyBoxes | G16: Report | H16: Report/PDF | I16: Medium | J16: High | K16: Open | L16: Development Team | M16: Abida Gul | N16: 46179 | O16: 46182 | P16: ERP Application - New Design | Q16: Two columns visible in the old design are not displayed in the new design. | Users cannot access complete information from the records list. | The table structure differs between old and new versions. | Data visibility is reduced in the new design. | R16: All columns available in the old design should also be displayed in the new design. | The table structure should remain consistent across both versions. | Users should have access to the same information regardless of the design version. | No column should be removed unless approved as part of a documented business requirement. | S16: Open the Money Boxes screen in the Old Design. | Navigate to the records list/grid section. | Note all available columns displayed in the table. | Open the same Money Boxes screen in the New Design. | Navigate to the records list/grid section. | Compare the table columns between the old and new screens. | Observe that two columns available in the old design are missing in the new design. | T16: The list/grid displayed in the New Design is missing two columns that are available and visible in the Old Design. As a result, users cannot view complete record information in the new screen. The table structure is inconsistent between both versions, causing functionality and reporting discrepancies. | U16: Document bug #15 | V16: Pending developer analysis
A17: MB-ND-016 | B17: Report Columns Mismatch in New Design Compared to Old Design – Collection/Lost Report | C17: Reports / Collection Report / Lost Report | E17: Collection / Lost Report | F17: https://10.10.10.154:200/moneybox/reports | G17: Report | H17: Report/PDF | I17: High | J17: High | K17: Open | L17: Development Team | M17: Abida Gul | N17: 46179 | O17: 46182 | P17: ERP Application - New Design | Q17: The New Design report displays only a limited number of columns. | Several fields available in the Old Design report are missing. | Report structure is inconsistent between old and new versions. | Users receive incomplete reporting information. | R17: The New Design report should contain all columns available in the Old Design report. | Column names and sequence should remain consistent unless officially approved. | Users should receive the same report output in both versions. | No business-critical field should be removed from the report. | S17: Open the Collection/Lost Report screen in the Old Design. | Generate the report using any valid search criteria. | Note the number and names of columns displayed in the report. | Open the same report in the New Design. | Generate the report using the same criteria. | Compare both reports. | Observe that multiple columns available in the old report are missing or renamed in the new report. | T17: The report generated in the New Design contains fewer columns than the report generated in the Old Design. Several important columns that were available in the old report are either missing or renamed in the new version. This results in incomplete reporting data and prevents users from accessing the full information required for operational and audit purposes. | U17: Document bug #16 | V17: Pending developer analysis
A18: MB-ND-017 | B18: Status Change Popup Size/Alignment Issue – Damage Money Boxes Screen | C18: Damage Money Boxes / الحصالات التالفة | E18: Damage Money Boxes / الحصالات التالفة | F18: https://10.10.10.154:200/moneybox/damageMoneyBoxes | G18: UI/UX | H18: UI/UX | I18: Medium | J18: Medium | K18: Open | L18: Development Team | M18: Abida Gul | N18: 46179 | O18: 46186 | P18: ERP Application - New Design | Q18: The popup contains a large empty content area. | Modal size is not adjusted according to the available fields. | Excessive white space is displayed below the status controls. | Popup layout appears misaligned and unoptimized. | R18: The popup should automatically resize according to its content. | Empty space should be removed. | Fields and controls should be properly aligned within the modal. | The dialog should have a clean and professional appearance consistent with the application design standards. | S18: Open the Damage Money Boxes screen using the URL: | https://10.10.10.154:200/moneybox/damageMoneyBoxes | Select any record from the list. | Click the Change Status (تغيير الحالة) button/action. | Observe the popup/modal that appears. | Review the content area inside the popup. | T18: When the user clicks the Change Status (تغيير الحالة) action, a popup/modal window is displayed. However, the popup content area is not properly sized and contains excessive empty space. The modal layout appears broken or improperly aligned, resulting in a poor user experience and inefficient use of screen space. | U18: Document bug #17 | V18: Pending developer analysis
A19: MB-ND-018 | B19: Dropdown Values Displayed in English Instead of Arabic – Damage Money Boxes Screen | C19: Damage Money Boxes / الحصالات التالفة | E19: Damage Money Boxes / الحصالات التالفة | F19: https://10.10.10.154:200/moneybox/damageMoneyBoxes | G19: Localization | H19: Dropdown/Localization | I19: Medium | J19: Medium | K19: Open | L19: Development Team | M19: Abida Gul | N19: 46179 | O19: 46186 | P19: ERP Application - New Design | Q19: Dropdown contains English values such as: | Repair | garbage | Language is inconsistent with the Arabic user interface. | Users may experience confusion due to mixed-language content. | R19: All dropdown values should be displayed in Arabic. | Suggested translations: | Repair → إصلاح | Garbage → إتلاف or نفايات (according to business requirements) | The entire screen should maintain a consistent Arabic language interface. | S19: Open the Damage Money Boxes screen using the URL: | https://10.10.10.154:200/moneybox/damageMoneyBoxes | Navigate to the search/filter section. | Click on the Status (الحالة) dropdown. | Review the available dropdown values. | Observe that some values are displayed in English. | T19: In the Damage Money Boxes screen, the status dropdown contains values displayed in English (e.g., "Repair" and "garbage"), while the application interface is configured in Arabic. Dropdown values should be translated and displayed in Arabic to maintain language consistency throughout the system. | U19: Document bug #18 | V19: Pending developer analysis
A20: MB-ND-019 | B20: Section Data and Selection Checkbox Missing in New Design – Bag Requests Processing Screen | C20: Bag Requests Processing / معالجة طلبات أكياس الأموال | E20: Process Bag Requests / معالجة طلبات أكياس الأموال | F20: https://10.10.10.154:200/moneybox/processBagRequests | G20: Functional | H20: Missing Field/Column | I20: High | J20: High | K20: Open | L20: Development Team | M20: Abida Gul | N20: 46179 | O20: 46182 | P20: ERP Application - New Design | Q20: The Section (القطاع) column is displayed but its data is missing/blank. | Record selection checkboxes are not available in the grid. | Users cannot identify the related section for each record. | Users cannot select records for processing actions. | R20: The Section (القطاع) column should display the correct section data for each record. | Selection checkboxes should be available for all records as in the old design. | Users should be able to select one or multiple records for processing. | Grid functionality and data visibility should match the old design. | S20: Open the Process Bag Requests screen using the URL: | https://10.10.10.154:200/moneybox/processBagRequests | Search for any available records. | Review the records displayed in the grid. | Compare the screen with the old design. | Observe the Section (القطاع) column and record selection functionality. | T20: In the new design of the Process Bag Requests screen, the Section (القطاع) column data is not displayed in the records grid. Additionally, the selection checkbox column that exists in the old design is missing. Due to this issue, users cannot view section information and are unable to select records for further processing. | U20: Document bug #19 | V20: Pending developer analysis
A21: MB-ND-020 | B21: Success Message Displayed Without Record Selection – Bag Requests Processing Screen | C21: Bag Requests Processing / معالجة طلبات أكياس الأموال | E21: Process Bag Requests / معالجة طلبات أكياس الأموال | F21: https://10.10.10.154:200/moneybox/processBagRequests | G21: Validation | H21: Validation | I21: High | J21: High | K21: Open | L21: Development Team | M21: Abida Gul | N21: 46179 | O21: 46182 | P21: ERP Application - New Design | Q21: The system displays a success message: | "تم الحفظ بنجاح" (Saved Successfully). | No record is selected for approval. | No validation message is shown. | User is misled into believing an approval action was completed. | R21: The system should validate record selection before processing. | If no record is selected, a warning/error message should appear such as: | "يرجى اختيار سجل واحد على الأقل." | (Please select at least one record.) | The approval process should not proceed until a valid selection is made. | Success messages should only be displayed after successful processing of selected records. | S21: Open the Process Bag Requests screen using the URL: | https://10.10.10.154:200/moneybox/processBagRequests | Search for available records. | Do not select any record from the list. | Click the Approve (موافقة) button. | Observe the system response. | T21: On the Process Bag Requests screen, when the user clicks the Approve (موافقة) button without selecting any record from the grid, the system incorrectly displays a success message ("تم الحفظ بنجاح"). The system should validate that at least one record is selected before processing the approval request. | U21: Document bug #20 | V21: Pending developer analysis
A22: MB-ND-021 | B22: Department Column Missing in Employee Committee Report – New Design | C22: Reports / Committee Employees Report / تقرير موظفين اللجنة | E22: Committee Employees Report / تقرير موظفين اللجنة | F22: https://10.10.10.154:200/moneybox/committeeEmployeesReport | G22: Report | H22: Report/PDF | I22: Medium | J22: Medium | K22: Open | L22: Development Team | M22: Abida Gul | N22: 46179 | O22: 46186 | P22: ERP Application - New Design | Q22: The report is generated successfully. | Employee information is displayed. | The Department (القسم) column is not available in the report. | Users cannot identify the department associated with each employee record. | R22: The report should include the Department (القسم) column as available in the old design. | All report columns should match the old report structure. | Users should be able to view complete employee details, including department information. | S22: Open the Employee Committee Report screen using the URL: | https://10.10.10.154:200/moneybox/committeeEmployeesReport | Enter a valid date range. | Click Search (بحث) to generate the report. | Review the report columns displayed in the grid. | Compare the report with the old design version. | Observe that the Department (القسم) column is missing. | T22: In the Employee Committee Report screen, the new design appears to be missing the Department (القسم) column that was available in the old report. This results in incomplete employee information being displayed and creates inconsistency between the old and new report layouts. | U22: Document bug #21 | V22: Pending developer analysis
A23: MB-ND-022 | B23: Record Selection Checkbox Missing in Transfer Bags Screen – New Design | C23: Transfer Bags | E23: Transfer Bags / نقل الأكياس | F23: https://10.10.10.154:200/moneybox/listTransfer | G23: Functional | H23: Missing Field/Column | I23: High | J23: High | K23: Open | L23: Development Team | M23: Abida Gul | N23: 46179 | O23: 46182 | P23: ERP Application - New Design | Q23: No checkbox column is displayed in the records grid. | Users cannot select records individually. | Bulk or record-based transfer actions cannot be performed properly. | Functionality differs from the old design. | R23: A checkbox column should be displayed for each record. | Users should be able to select one or multiple records. | Transfer operations should support record selection as implemented in the old design. | The new design should maintain the same functionality as the old system. | S23: Open the Transfer Bags screen using the URL: | https://10.10.10.154:200/moneybox/listTransfer | Search for available records. | Review the records grid displayed on the page. | Compare the screen with the old design. | Observe the area where record selection checkboxes should appear. | T23: In the Transfer Bags screen, the record selection checkbox column is missing in the new design. Users are unable to select one or multiple records from the list for transfer-related actions. The checkbox functionality available in the old design is not present in the new screen. | U23: Document bug #22 | V23: Pending developer analysis

Sheet Summary
A1: Bug Report Summary
A3: Severity | B3: Count | D3: Priority | E3: Count | G3: Status | H3: Count
A4: High | B4: =COUNTIF('Bug Tracker'!$I$2:$I$100,"High") -> 14 | D4: High | E4: =COUNTIF('Bug Tracker'!$J$2:$J$100,"High") -> 18 | G4: Open | H4: =COUNTIF('Bug Tracker'!$K$2:$K$100,"Open") -> 22
A5: Medium / High | B5: =COUNTIF('Bug Tracker'!$I$2:$I$100,"Medium / High") -> 3 | D5: Medium | E5: =COUNTIF('Bug Tracker'!$J$2:$J$100,"Medium") -> 4 | G5: In Progress | H5: =COUNTIF('Bug Tracker'!$K$2:$K$100,"In Progress") -> 0
A6: Medium | B6: =COUNTIF('Bug Tracker'!$I$2:$I$100,"Medium") -> 4 | D6: Low | E6: =COUNTIF('Bug Tracker'!$J$2:$J$100,"Low") -> 0 | G6: Blocked | H6: =COUNTIF('Bug Tracker'!$K$2:$K$100,"Blocked") -> 0
A7: Low / Medium | B7: =COUNTIF('Bug Tracker'!$I$2:$I$100,"Low / Medium") -> 1 | D7: Critical | E7: =COUNTIF('Bug Tracker'!$J$2:$J$100,"Critical") -> 0 | G7: Ready for Retest | H7: =COUNTIF('Bug Tracker'!$K$2:$K$100,"Ready for Retest") -> 0
A8: Low | B8: =COUNTIF('Bug Tracker'!$I$2:$I$100,"Low") -> 0 | G8: Closed | H8: =COUNTIF('Bug Tracker'!$K$2:$K$100,"Closed") -> 0
A11: Category | B11: Count | D11: Module | E11: Count
A12: Add/Save Error | B12: =COUNTIF('Bug Tracker'!$H$2:$H$100,"Add/Save Error") -> 2 | D12: Money Box / الحصالات | E12: 15
A13: Data Display/Refresh | B13: =COUNTIF('Bug Tracker'!$H$2:$H$100,"Data Display/Refresh") -> 4 | D13: Damage Money Boxes / الحصالات التالفة | E13: 2
A14: Delete | B14: =COUNTIF('Bug Tracker'!$H$2:$H$100,"Delete") -> 1 | D14: Bag Requests Processing / معالجة طلبات أكياس الأموال | E14: 2
A15: Dropdown/Localization | B15: =COUNTIF('Bug Tracker'!$H$2:$H$100,"Dropdown/Localization") -> 2 | D15: Reports / Collection Report / Lost Report | E15: 1
A16: Missing Field/Column | B16: =COUNTIF('Bug Tracker'!$H$2:$H$100,"Missing Field/Column") -> 4 | D16: Reports / Committee Employees Report / تقرير موظفين اللجنة | E16: 1
A17: Report/PDF | B17: =COUNTIF('Bug Tracker'!$H$2:$H$100,"Report/PDF") -> 5 | D17: Transfer Bags | E17: 1
A18: Status/Toggle | B18: =COUNTIF('Bug Tracker'!$H$2:$H$100,"Status/Toggle") -> 1
A19: UI/UX | B19: =COUNTIF('Bug Tracker'!$H$2:$H$100,"UI/UX") -> 2
A20: Validation | B20: =COUNTIF('Bug Tracker'!$H$2:$H$100,"Validation") -> 1

Sheet Defect Details
A1: MB-ND-001 - Old request/record becomes hidden after editing and saving in Money Boxes screen | B1: MB-ND-001 - Old request/record becomes hidden after editing and saving in Money Boxes screen | C1: MB-ND-001 - Old request/record becomes hidden after editing and saving in Money Boxes screen | D1: MB-ND-001 - Old request/record becomes hidden after editing and saving in Money Boxes screen
A2: Screen/Page | B2: Money Boxes / الحصالات
A3: Severity / Priority | B3: High / High
A4: Actual Result | B4: After editing and saving the old request, the record becomes hidden or does not appear properly in the table. | User cannot clearly confirm whether the update was saved successfully. | Table/list view does not refresh or display the updated record correctly.
A5: Expected Result | B5: After editing and saving, the updated record should remain visible in the table. | The table should refresh properly and show the latest updated data. | User should receive a success message after saving. | No record should disappear or become hidden after update.
A6: Steps | B6: Open the Money Boxes screen using this URL: | https://10.10.10.154:200/moneybox/moneyBoxes | Search or select an existing/old request from the table. | Click on the تعديل button for any existing record. | Update any required field. | Click the save/update button. | Return to the table/list view. | Observe that the edited record is hidden or not displayed correctly in the table.
A7: MB-ND-002 - Error occurs when adding new Money Box and clicking Save | B7: MB-ND-002 - Error occurs when adding new Money Box and clicking Save | C7: MB-ND-002 - Error occurs when adding new Money Box and clicking Save | D7: MB-ND-002 - Error occurs when adding new Money Box and clicking Save
A8: Screen/Page | B8: Money Boxes / الحصالات
A9: Severity / Priority | B9: High / High
A10: Actual Result | B10: The system displays an error message after clicking حفظ. | New Money Box is not saved. | User cannot complete the add process successfully. | Error message appears | "حدث خطأ. يرجى التواصل مع الدعم الفني إذا استمر هذا الخطأ"
A11: Expected Result | B11: New Money Box should be saved successfully. | System should show a success message after saving. | The newly added Money Box should appear in the Money Boxes table/list. | No error message should appear.
A12: Steps | B12: Open the Money Boxes screen using the URL: | https://10.10.10.154:200/moneybox/moneyBoxes | Click on the إضافة / Add button. | The إضافة حصالة جديدة form will open. | Fill in the required fields, such as: | نوع / Type | كود رئيسي / Main Code | كود / Code | الرقم / Number | تصنيف الحصالة / Money Box Classification | Click on the حفظ button. | Observe the error message displayed on the screen.
A13: MB-ND-003 - Error occurs when adding new Section Grouping and clicking Save | B13: MB-ND-003 - Error occurs when adding new Section Grouping and clicking Save | C13: MB-ND-003 - Error occurs when adding new Section Grouping and clicking Save | D13: MB-ND-003 - Error occurs when adding new Section Grouping and clicking Save
A14: Screen/Page | B14: Money Boxes → Sections Grouping / مجموعة الحصالات
A15: Severity / Priority | B15: High / High
A16: Actual Result | B16: The system displays an error message after clicking حفظ. | New Section Grouping is not saved. | User cannot complete the add process successfully. | Error message appears: | "حدث خطأ. يرجى التواصل مع الدعم الفني إذا استمر هذا الخطأ"
A17: Expected Result | B17: New Section Grouping should be saved successfully. | System should show a success message after saving. | The newly added Section Grouping should appear in the list/table. | No error message should appear.
A18: Steps | B18: Open the Section Grouping screen using the URL: | https://10.10.10.154:200/moneybox/sections/sectionsGrouping/a64e09d7-5f17-eb11-81d7-000c29d5b0c7 | Click on the إضافة / Add button. | The إضافة مجموعة form will open. | Fill in the required fields, such as: | التصنيف / Classification | رقم المجموعة / Group Number | Click on the حفظ button. | Observe the error message displayed on the screen.
A19: MB-ND-004 - Add button is missing in Assign Money Box subsection screen | B19: MB-ND-004 - Add button is missing in Assign Money Box subsection screen | C19: MB-ND-004 - Add button is missing in Assign Money Box subsection screen | D19: MB-ND-004 - Add button is missing in Assign Money Box subsection screen
A20: Screen/Page | B20: Money Boxes → Sections → Assign Money Box / تعيين حصالة
A21: Severity / Priority | B21: Medium / High / High
A22: Actual Result | B22: Add / إضافة button is missing from the subsection screen. | User cannot add or assign a new Money Box. | User is unable to perform the required assignment action from this page.
A23: Expected Result | B23: Add / إضافة button should be available on the Assign Money Box subsection screen. | User should be able to click the Add button and assign a new Money Box. | The newly assigned Money Box should appear in the table/list after saving.
A24: Steps | B24: Open the Assign Money Box screen using the URL: | https://10.10.10.154:200/moneybox/sections/assignMoneybox/3ff57db3-3d62-f111-8272-000c29b5ee4d | Check the top section of the page. | Check the Money Boxes table/list area. | Check the Assign Money Box section. | Observe that there is no Add / إضافة button available.
A25: MB-ND-005 - Group title/alignment is not displayed properly on Assign Money Box screen | B25: MB-ND-005 - Group title/alignment is not displayed properly on Assign Money Box screen | C25: MB-ND-005 - Group title/alignment is not displayed properly on Assign Money Box screen | D25: MB-ND-005 - Group title/alignment is not displayed properly on Assign Money Box screen
A26: Screen/Page | B26: Money Boxes → Sections → Assign Money Box / تعيين حصالة
A27: Severity / Priority | B27: Low / Medium / Medium
A28: Actual Result | B28: Group title is not aligned properly. | Arabic and English text appear mixed incorrectly. | The displayed title looks like: | رقم المجموعة : 3510 ----------- Test project | Text direction/spacing is not properly handled.
A29: Expected Result | B29: Group title should be displayed clearly and properly aligned. | Arabic and English text should follow correct RTL/LTR formatting. | The title should appear in a clean and readable format, for example: | رقم المجموعة: 3510 - Test project | No broken spacing or unnecessary dashes should appear.
A30: Steps | B30: Open the Assign Money Box screen using this URL: | https://10.10.10.154:200/moneybox/sections/assignMoneybox/3ff57db3-3d62-f111-8272-000c29b5ee4d | Check the group title displayed at the top-right side of the page. | Observe the text formatting and alignment.
A31: MB-ND-006 - Deleted record shows success message but data is not removed from Sub Money Box Type list | B31: MB-ND-006 - Deleted record shows success message but data is not removed from Sub Money Box Type list | C31: MB-ND-006 - Deleted record shows success message but data is not removed from Sub Money Box Type list | D31: MB-ND-006 - Deleted record shows success message but data is not removed from Sub Money Box Type list
A32: Screen/Page | B32: Money Boxes → Sub Money Box Type / نوع الحصالات الفرعي
A33: Severity / Priority | B33: Medium / High / High
A34: Actual Result | B34: System shows success message: | "تم الحذف بنجاح" | The selected record is still visible in the list. | Data is not removed from the table after delete. | User cannot confirm whether the record was actually deleted from the database or only the UI failed to refresh.
A35: Expected Result | B35: After clicking Delete, the selected record should be removed successfully. | The deleted record should disappear from the table/list. | Table should refresh automatically after successful deletion. | Success message should appear only when the record is actually deleted.
A36: Steps | B36: Open the Sub Money Box Type screen using the URL: | https://10.10.10.154:200/moneybox/moneyboxSubTypes | Select any existing record from the list. | Click on the حذف / Delete button. | Confirm the delete action, if confirmation popup appears. | Observe the success message. | Check the table/list after deletion.
A37: MB-ND-007 - New Sub Money Box Type shows success message but data is not added in the list | B37: MB-ND-007 - New Sub Money Box Type shows success message but data is not added in the list | C37: MB-ND-007 - New Sub Money Box Type shows success message but data is not added in the list | D37: MB-ND-007 - New Sub Money Box Type shows success message but data is not added in the list
A38: Screen/Page | B38: Money Boxes → Sub Money Box Type / نوع الحصالات الفرعي
A39: Severity / Priority | B39: High / High
A40: Actual Result | B40: System shows a success message after saving. | Newly added data does not appear in the list/table. | User cannot confirm whether the data was saved successfully. | The table does not refresh or display the newly added record.
...

Sheet Lists
A1: Status | B1: Priority | C1: Severity | D1: Defect Type
A2: Open | B2: High | C2: High | D2: Functional
A3: In Progress | B3: Medium | C3: Medium / High | D3: UI/UX
A4: Blocked | B4: Low | C4: Medium | D4: Report
A5: Ready for Retest | B5: Critical | C5: Low / Medium | D5: Localization
A6: Closed | C6: Low | D6: Validation
D7: Data
D8: Integration
D9: Security
